2023-12-19 05:57:28,577 INFO: hub_startup [in /home/py_sama/rapid_care/app/__init__.py : 53]
2023-12-19 05:57:44,813 ERROR: Exception on /auth/logout [GET] [in /home/py_sama/flask_environment/lib/python3.11/site-packages/flask/app.py : 825]
Traceback (most recent call last):
  File "/home/py_sama/flask_environment/lib/python3.11/site-packages/flask/app.py", line 1455, in wsgi_app
    response = self.full_dispatch_request()
               ^^^^^^^^^^^^^^^^^^^^^^^^^^^^
  File "/home/py_sama/flask_environment/lib/python3.11/site-packages/flask/app.py", line 869, in full_dispatch_request
    rv = self.handle_user_exception(e)
         ^^^^^^^^^^^^^^^^^^^^^^^^^^^^^
  File "/home/py_sama/flask_environment/lib/python3.11/site-packages/flask/app.py", line 867, in full_dispatch_request
    rv = self.dispatch_request()
         ^^^^^^^^^^^^^^^^^^^^^^^
  File "/home/py_sama/flask_environment/lib/python3.11/site-packages/flask/app.py", line 852, in dispatch_request
    return self.ensure_sync(self.view_functions[rule.endpoint])(**view_args)
           ^^^^^^^^^^^^^^^^^^^^^^^^^^^^^^^^^^^^^^^^^^^^^^^^^^^^^^^^^^^^^^^^^
  File "/home/py_sama/rapid_care/app/auth/routes.py", line 49, in logout
    return redirect(url_for('index'))
                    ^^^^^^^^^^^^^^^^
  File "/home/py_sama/flask_environment/lib/python3.11/site-packages/flask/helpers.py", line 222, in url_for
    return current_app.url_for(
           ^^^^^^^^^^^^^^^^^^^^
  File "/home/py_sama/flask_environment/lib/python3.11/site-packages/flask/app.py", line 1071, in url_for
    return self.handle_url_build_error(error, endpoint, values)
           ^^^^^^^^^^^^^^^^^^^^^^^^^^^^^^^^^^^^^^^^^^^^^^^^^^^^
  File "/home/py_sama/flask_environment/lib/python3.11/site-packages/flask/app.py", line 1060, in url_for
    rv = url_adapter.build(  # type: ignore[union-attr]
         ^^^^^^^^^^^^^^^^^^^^^^^^^^^^^^^^^^^^^^^^^^^^^^
  File "/home/py_sama/flask_environment/lib/python3.11/site-packages/werkzeug/routing/map.py", line 919, in build
    raise BuildError(endpoint, values, method, self)
werkzeug.routing.exceptions.BuildError: Could not build url for endpoint 'index'. Did you mean 'main.index' instead?
2023-12-19 05:59:42,639 ERROR: Exception on /auth/logout [GET] [in /home/py_sama/flask_environment/lib/python3.11/site-packages/flask/app.py : 825]
Traceback (most recent call last):
  File "/home/py_sama/flask_environment/lib/python3.11/site-packages/flask/app.py", line 1455, in wsgi_app
    response = self.full_dispatch_request()
               ^^^^^^^^^^^^^^^^^^^^^^^^^^^^
  File "/home/py_sama/flask_environment/lib/python3.11/site-packages/flask/app.py", line 869, in full_dispatch_request
    rv = self.handle_user_exception(e)
         ^^^^^^^^^^^^^^^^^^^^^^^^^^^^^
  File "/home/py_sama/flask_environment/lib/python3.11/site-packages/flask/app.py", line 867, in full_dispatch_request
    rv = self.dispatch_request()
         ^^^^^^^^^^^^^^^^^^^^^^^
  File "/home/py_sama/flask_environment/lib/python3.11/site-packages/flask/app.py", line 852, in dispatch_request
    return self.ensure_sync(self.view_functions[rule.endpoint])(**view_args)
           ^^^^^^^^^^^^^^^^^^^^^^^^^^^^^^^^^^^^^^^^^^^^^^^^^^^^^^^^^^^^^^^^^
  File "/home/py_sama/rapid_care/app/auth/routes.py", line 49, in logout
    return redirect(url_for('index'))
                    ^^^^^^^^^^^^^^^^
  File "/home/py_sama/flask_environment/lib/python3.11/site-packages/flask/helpers.py", line 222, in url_for
    return current_app.url_for(
           ^^^^^^^^^^^^^^^^^^^^
  File "/home/py_sama/flask_environment/lib/python3.11/site-packages/flask/app.py", line 1071, in url_for
    return self.handle_url_build_error(error, endpoint, values)
           ^^^^^^^^^^^^^^^^^^^^^^^^^^^^^^^^^^^^^^^^^^^^^^^^^^^^
  File "/home/py_sama/flask_environment/lib/python3.11/site-packages/flask/app.py", line 1060, in url_for
    rv = url_adapter.build(  # type: ignore[union-attr]
         ^^^^^^^^^^^^^^^^^^^^^^^^^^^^^^^^^^^^^^^^^^^^^^
  File "/home/py_sama/flask_environment/lib/python3.11/site-packages/werkzeug/routing/map.py", line 919, in build
    raise BuildError(endpoint, values, method, self)
werkzeug.routing.exceptions.BuildError: Could not build url for endpoint 'index'. Did you mean 'main.index' instead?
2023-12-22 17:01:47,159 INFO: hub_startup [in /home/py_sama/rapid_care/app/__init__.py : 53]
2023-12-22 17:05:44,286 INFO: hub_startup [in /home/py_sama/rapid_care/app/__init__.py : 53]
2023-12-22 17:05:48,681 ERROR: Exception on /chatbot/12 [GET] [in /home/py_sama/flask_environment/lib/python3.11/site-packages/flask/app.py : 825]
Traceback (most recent call last):
  File "/home/py_sama/flask_environment/lib/python3.11/site-packages/flask/app.py", line 1455, in wsgi_app
    response = self.full_dispatch_request()
               ^^^^^^^^^^^^^^^^^^^^^^^^^^^^
  File "/home/py_sama/flask_environment/lib/python3.11/site-packages/flask/app.py", line 869, in full_dispatch_request
    rv = self.handle_user_exception(e)
         ^^^^^^^^^^^^^^^^^^^^^^^^^^^^^
  File "/home/py_sama/flask_environment/lib/python3.11/site-packages/flask/app.py", line 867, in full_dispatch_request
    rv = self.dispatch_request()
         ^^^^^^^^^^^^^^^^^^^^^^^
  File "/home/py_sama/flask_environment/lib/python3.11/site-packages/flask/app.py", line 852, in dispatch_request
    return self.ensure_sync(self.view_functions[rule.endpoint])(**view_args)
           ^^^^^^^^^^^^^^^^^^^^^^^^^^^^^^^^^^^^^^^^^^^^^^^^^^^^^^^^^^^^^^^^^
  File "/home/py_sama/flask_environment/lib/python3.11/site-packages/flask_login/utils.py", line 290, in decorated_view
    return current_app.ensure_sync(func)(*args, **kwargs)
           ^^^^^^^^^^^^^^^^^^^^^^^^^^^^^^^^^^^^^^^^^^^^^^
  File "/home/py_sama/rapid_care/app/main/routes.py", line 91, in chatbot
    return render_template('chatbot.html',title='login',form1=form1,chat_form=chat_form,conversation=conversation)
           ^^^^^^^^^^^^^^^^^^^^^^^^^^^^^^^^^^^^^^^^^^^^^^^^^^^^^^^^^^^^^^^^^^^^^^^^^^^^^^^^^^^^^^^^^^^^^^^^^^^^^^^
  File "/home/py_sama/flask_environment/lib/python3.11/site-packages/flask/templating.py", line 152, in render_template
    return _render(app, template, context)
           ^^^^^^^^^^^^^^^^^^^^^^^^^^^^^^^
  File "/home/py_sama/flask_environment/lib/python3.11/site-packages/flask/templating.py", line 133, in _render
    rv = template.render(context)
         ^^^^^^^^^^^^^^^^^^^^^^^^
  File "/home/py_sama/flask_environment/lib/python3.11/site-packages/jinja2/environment.py", line 1301, in render
    self.environment.handle_exception()
  File "/home/py_sama/flask_environment/lib/python3.11/site-packages/jinja2/environment.py", line 936, in handle_exception
    raise rewrite_traceback_stack(source=source)
  File "/home/py_sama/rapid_care/app/templates/chatbot.html", line 1, in top-level template code
    {% extends 'base.html' %}
  File "/home/py_sama/rapid_care/app/templates/base.html", line 37, in top-level template code
    {% block content %}
  File "/home/py_sama/rapid_care/app/templates/chatbot.html", line 23, in block 'content'
    {{form1.message(class='fixed-bottom')}}
    ^^^^^^^^^^^^^^^^^^^^^^^^^
  File "/home/py_sama/flask_environment/lib/python3.11/site-packages/jinja2/utils.py", line 83, in from_obj
    if hasattr(obj, "jinja_pass_arg"):
       ^^^^^^^^^^^^^^^^^^^^^^^^^^^^^^
jinja2.exceptions.UndefinedError: 'app.main.form.Chatbot object' has no attribute 'message'
2023-12-23 05:42:56,741 INFO: hub_startup [in /home/py_sama/rapid_care/app/__init__.py : 53]
2023-12-23 05:43:25,461 ERROR: Exception on /auth/logout [GET] [in /home/py_sama/flask_environment/lib/python3.11/site-packages/flask/app.py : 825]
Traceback (most recent call last):
  File "/home/py_sama/flask_environment/lib/python3.11/site-packages/flask/app.py", line 1455, in wsgi_app
    response = self.full_dispatch_request()
               ^^^^^^^^^^^^^^^^^^^^^^^^^^^^
  File "/home/py_sama/flask_environment/lib/python3.11/site-packages/flask/app.py", line 869, in full_dispatch_request
    rv = self.handle_user_exception(e)
         ^^^^^^^^^^^^^^^^^^^^^^^^^^^^^
  File "/home/py_sama/flask_environment/lib/python3.11/site-packages/flask/app.py", line 867, in full_dispatch_request
    rv = self.dispatch_request()
         ^^^^^^^^^^^^^^^^^^^^^^^
  File "/home/py_sama/flask_environment/lib/python3.11/site-packages/flask/app.py", line 852, in dispatch_request
    return self.ensure_sync(self.view_functions[rule.endpoint])(**view_args)
           ^^^^^^^^^^^^^^^^^^^^^^^^^^^^^^^^^^^^^^^^^^^^^^^^^^^^^^^^^^^^^^^^^
  File "/home/py_sama/rapid_care/app/auth/routes.py", line 49, in logout
    return redirect(url_for('index'))
                    ^^^^^^^^^^^^^^^^
  File "/home/py_sama/flask_environment/lib/python3.11/site-packages/flask/helpers.py", line 222, in url_for
    return current_app.url_for(
           ^^^^^^^^^^^^^^^^^^^^
  File "/home/py_sama/flask_environment/lib/python3.11/site-packages/flask/app.py", line 1071, in url_for
    return self.handle_url_build_error(error, endpoint, values)
           ^^^^^^^^^^^^^^^^^^^^^^^^^^^^^^^^^^^^^^^^^^^^^^^^^^^^
  File "/home/py_sama/flask_environment/lib/python3.11/site-packages/flask/app.py", line 1060, in url_for
    rv = url_adapter.build(  # type: ignore[union-attr]
         ^^^^^^^^^^^^^^^^^^^^^^^^^^^^^^^^^^^^^^^^^^^^^^
  File "/home/py_sama/flask_environment/lib/python3.11/site-packages/werkzeug/routing/map.py", line 919, in build
    raise BuildError(endpoint, values, method, self)
werkzeug.routing.exceptions.BuildError: Could not build url for endpoint 'index'. Did you mean 'main.index' instead?
