2024-01-02 07:22:13,026 ERROR: Exception on /api/users/1/chats [POST] [in /home/py_sama/rapid_care/rapid_care_environment/lib/python3.11/site-packages/flask/app.py : 825]
Traceback (most recent call last):
  File "/home/py_sama/rapid_care/rapid_care_environment/lib/python3.11/site-packages/flask/app.py", line 1455, in wsgi_app
    response = self.full_dispatch_request()
               ^^^^^^^^^^^^^^^^^^^^^^^^^^^^
  File "/home/py_sama/rapid_care/rapid_care_environment/lib/python3.11/site-packages/flask/app.py", line 869, in full_dispatch_request
    rv = self.handle_user_exception(e)
         ^^^^^^^^^^^^^^^^^^^^^^^^^^^^^
  File "/home/py_sama/rapid_care/rapid_care_environment/lib/python3.11/site-packages/flask/app.py", line 867, in full_dispatch_request
    rv = self.dispatch_request()
         ^^^^^^^^^^^^^^^^^^^^^^^
  File "/home/py_sama/rapid_care/rapid_care_environment/lib/python3.11/site-packages/flask/app.py", line 852, in dispatch_request
    return self.ensure_sync(self.view_functions[rule.endpoint])(**view_args)
           ^^^^^^^^^^^^^^^^^^^^^^^^^^^^^^^^^^^^^^^^^^^^^^^^^^^^^^^^^^^^^^^^^
  File "/home/py_sama/rapid_care/app/api/users.py", line 57, in add_chat
    conversation.from_dict(id,conversation_no=conversation_no,new_chat=True)
  File "/home/py_sama/rapid_care/app/models.py", line 167, in from_dict
    message.get_response()
  File "/home/py_sama/rapid_care/app/chat/chat.py", line 42, in get_response
    full_response = client.chat.completions.create(
                    ^^^^^^^^^^^^^^^^^^^^^^^^^^^^^^^
  File "/home/py_sama/rapid_care/rapid_care_environment/lib/python3.11/site-packages/openai/_utils/_utils.py", line 272, in wrapper
    return func(*args, **kwargs)
           ^^^^^^^^^^^^^^^^^^^^^
  File "/home/py_sama/rapid_care/rapid_care_environment/lib/python3.11/site-packages/openai/resources/chat/completions.py", line 645, in create
    return self._post(
           ^^^^^^^^^^^
  File "/home/py_sama/rapid_care/rapid_care_environment/lib/python3.11/site-packages/openai/_base_client.py", line 1088, in post
    return cast(ResponseT, self.request(cast_to, opts, stream=stream, stream_cls=stream_cls))
                           ^^^^^^^^^^^^^^^^^^^^^^^^^^^^^^^^^^^^^^^^^^^^^^^^^^^^^^^^^^^^^^^^^
  File "/home/py_sama/rapid_care/rapid_care_environment/lib/python3.11/site-packages/openai/_base_client.py", line 853, in request
    return self._request(
           ^^^^^^^^^^^^^^
  File "/home/py_sama/rapid_care/rapid_care_environment/lib/python3.11/site-packages/openai/_base_client.py", line 930, in _request
    raise self._make_status_error_from_response(err.response) from None
openai.AuthenticationError: Error code: 401 - {'error': {'message': 'Incorrect API key provided: sk-9NRVz***************************************XC9u. You can find your API key at https://platform.openai.com/account/api-keys.', 'type': 'invalid_request_error', 'param': None, 'code': 'invalid_api_key'}}
2024-01-02 07:22:35,765 INFO: hub_startup [in /home/py_sama/rapid_care/app/__init__.py : 80]
2024-01-02 07:22:35,765 INFO: hub_startup [in /home/py_sama/rapid_care/app/__init__.py : 80]
2024-01-02 07:22:35,769 INFO: hub_startup [in /home/py_sama/rapid_care/app/__init__.py : 80]
2024-01-02 07:22:35,773 INFO: hub_startup [in /home/py_sama/rapid_care/app/__init__.py : 80]
2024-01-02 07:22:46,425 ERROR: Exception on /api/users/1/chats [POST] [in /home/py_sama/rapid_care/rapid_care_environment/lib/python3.11/site-packages/flask/app.py : 825]
Traceback (most recent call last):
  File "/home/py_sama/rapid_care/rapid_care_environment/lib/python3.11/site-packages/flask/app.py", line 1455, in wsgi_app
    response = self.full_dispatch_request()
               ^^^^^^^^^^^^^^^^^^^^^^^^^^^^
  File "/home/py_sama/rapid_care/rapid_care_environment/lib/python3.11/site-packages/flask/app.py", line 869, in full_dispatch_request
    rv = self.handle_user_exception(e)
         ^^^^^^^^^^^^^^^^^^^^^^^^^^^^^
  File "/home/py_sama/rapid_care/rapid_care_environment/lib/python3.11/site-packages/flask/app.py", line 867, in full_dispatch_request
    rv = self.dispatch_request()
         ^^^^^^^^^^^^^^^^^^^^^^^
  File "/home/py_sama/rapid_care/rapid_care_environment/lib/python3.11/site-packages/flask/app.py", line 852, in dispatch_request
    return self.ensure_sync(self.view_functions[rule.endpoint])(**view_args)
           ^^^^^^^^^^^^^^^^^^^^^^^^^^^^^^^^^^^^^^^^^^^^^^^^^^^^^^^^^^^^^^^^^
  File "/home/py_sama/rapid_care/app/api/users.py", line 57, in add_chat
    conversation.from_dict(id,conversation_no=conversation_no,new_chat=True)
  File "/home/py_sama/rapid_care/app/models.py", line 167, in from_dict
    message.get_response()
  File "/home/py_sama/rapid_care/app/chat/chat.py", line 42, in get_response
    full_response = client.chat.completions.create(
                    ^^^^^^^^^^^^^^^^^^^^^^^^^^^^^^^
  File "/home/py_sama/rapid_care/rapid_care_environment/lib/python3.11/site-packages/openai/_utils/_utils.py", line 272, in wrapper
    return func(*args, **kwargs)
           ^^^^^^^^^^^^^^^^^^^^^
  File "/home/py_sama/rapid_care/rapid_care_environment/lib/python3.11/site-packages/openai/resources/chat/completions.py", line 645, in create
    return self._post(
           ^^^^^^^^^^^
  File "/home/py_sama/rapid_care/rapid_care_environment/lib/python3.11/site-packages/openai/_base_client.py", line 1088, in post
    return cast(ResponseT, self.request(cast_to, opts, stream=stream, stream_cls=stream_cls))
                           ^^^^^^^^^^^^^^^^^^^^^^^^^^^^^^^^^^^^^^^^^^^^^^^^^^^^^^^^^^^^^^^^^
  File "/home/py_sama/rapid_care/rapid_care_environment/lib/python3.11/site-packages/openai/_base_client.py", line 853, in request
    return self._request(
           ^^^^^^^^^^^^^^
  File "/home/py_sama/rapid_care/rapid_care_environment/lib/python3.11/site-packages/openai/_base_client.py", line 916, in _request
    return self._retry_request(
           ^^^^^^^^^^^^^^^^^^^^
  File "/home/py_sama/rapid_care/rapid_care_environment/lib/python3.11/site-packages/openai/_base_client.py", line 958, in _retry_request
    return self._request(
           ^^^^^^^^^^^^^^
  File "/home/py_sama/rapid_care/rapid_care_environment/lib/python3.11/site-packages/openai/_base_client.py", line 916, in _request
    return self._retry_request(
           ^^^^^^^^^^^^^^^^^^^^
  File "/home/py_sama/rapid_care/rapid_care_environment/lib/python3.11/site-packages/openai/_base_client.py", line 958, in _retry_request
    return self._request(
           ^^^^^^^^^^^^^^
  File "/home/py_sama/rapid_care/rapid_care_environment/lib/python3.11/site-packages/openai/_base_client.py", line 930, in _request
    raise self._make_status_error_from_response(err.response) from None
openai.RateLimitError: Error code: 429 - {'error': {'message': 'You exceeded your current quota, please check your plan and billing details. For more information on this error, read the docs: https://platform.openai.com/docs/guides/error-codes/api-errors.', 'type': 'insufficient_quota', 'param': None, 'code': 'insufficient_quota'}}
